<?xml version="1.0"?>
<robot xmlns:xacro="http://www.ros.org/wiki/xacro"  name="robot">
    <xacro:include filename="inertial_macros.xacro"/>
    <material name="blue">
        <color rgba="0 0 1 1"/>
    </material>
    <material name="red">
        <color rgba="1 0 0 1"/>
    </material>
    <material name="green">
        <color rgba="0 1 0 1"/>
    </material>
    <material name="black">
        <color rgba="0 0 0 1"/>
    </material>
    <material name="white">
        <color rgba="1 1 1 1"/>
    </material>
    <link name="base_link">
    </link>
    <joint name="chassis_joint" type="fixed">
        <parent link="base_link"/>
        <child link="chassis"/>
        <origin xyz="-0.1125 0 0"/>
    </joint>
    <link name="chassis">
        <visual>
            <origin xyz="0.1125 0 0.055"/>
            <geometry>
                <box size="0.225 0.215 0.11"/>
            </geometry>
            <material name="white"/>
        </visual>
        <xacro:inertial_box mass="0.5" x="0.225" y="0.3" z="0.15">
            <origin xyz="0.15 0 0.075"/>
        </xacro:inertial_box>
        <collision>
            <origin xyz="0.1125 0 0.055"/>
            <geometry>
                <box size="0.225 0.215 0.11"/>
            </geometry>
        </collision>
    </link>
    <joint name="left_wheel_joint" type="continuous">
        <parent link="base_link"/>
        <child link="left_wheel"/> 
        <origin xyz="0 0.1075 0" rpy="-${pi/2} 0 0"/>
        <axis xyz="0 0 1"/>
    </joint>
    <link name="left_wheel">
        <visual>
            <geometry>
                <cylinder radius="0.035" length="0.017"/>
            </geometry>
            <material name="black"/>
        </visual>
        <collision>
            <geometry>
                <cylinder radius="0.035" length="0.017"/>
            </geometry>
        </collision>
        <xacro:inertial_cylinder mass="0.1" length="0.017" radius="0.035">
            <origin xyz="0.15 0 0.075" rpy="0 0 0"/>
        </xacro:inertial_cylinder>
    </link>
    <joint name="right_wheel_joint" type="continuous">
        <parent link="base_link"/>
        <child link="right_wheel"/> 
        <origin xyz="0 -0.1075 0" rpy="${pi/2} 0 0"/>
        <axis xyz="0 0 -1"/>
    </joint>
    <link name="right_wheel">
        <visual>
            <geometry>
                <cylinder radius="0.035" length="0.017"/>
            </geometry>
            <material name="black"/>
        </visual>
        <collision>
            <geometry>
                <cylinder radius="0.035" length="0.017"/>
            </geometry>
        </collision>
    </link>
</robot>