<?xml version="1.0"?>
<robot xmlns:xacro="http://www.ros.org/wiki/xacro"  name="robot">
    <xacro:include filename="inertial_macros.xacro"/>
    <material name="blue">
        <color rgba="0 0 1 1"/>
    </material>
    <material name="red">
        <color rgba="1 0 0 1"/>
    </material>
    <material name="green">
        <color rgba="0 1 0 1"/>
    </material>
    <material name="black">
        <color rgba="0 0 0 1"/>
    </material>
    <material name="white">
        <color rgba="1 1 1 1"/>
    </material>
    <link name="base_link">
    </link>
    <joint name="chassis_joint" type="fixed">
        <parent link="base_link"/>
        <child link="chassis"/>
        <origin xyz="-0.09 0 0"/>
    </joint>
    <link name="chassis">
        <visual>
            <origin xyz="0.1125 0 0.055"/>
            <geometry>
                <box size="0.225 0.145 0.11"/>
            </geometry>
            <material name="red"/>
        </visual>
        <xacro:inertial_box mass="0.5" x="0.225" y="0.145" z="0.11">
            <origin xyz="0.1125 0 0.055"/>
        </xacro:inertial_box>
        <collision>
            <origin xyz="0.1125 0 0.055"/>
            <geometry>
                <box size="0.225 0.215 0.11"/>
            </geometry>
        </collision>
    </link>
    <gazebo reference="chassis">
            <material>Gazebo/White</material>
    </gazebo>
    <joint name="left_wheel_joint" type="continuous">
        <parent link="base_link"/>
        <child link="left_wheel"/> 
        <origin xyz="0.08 0.087 0" rpy="-${pi/2} 0 0"/>
        <axis xyz="0 0 1"/>
    </joint>
    <link name="left_wheel">
        <visual>
            <geometry>
                <cylinder radius="0.035" length="0.017"/>
            </geometry>
            <material name="black"/>
        </visual>
        <collision>
            <geometry>
                <cylinder radius="0.035" length="0.017"/>
            </geometry>
        </collision>
        <xacro:inertial_cylinder mass="0.1" length="0.017" radius="0.035">
            <origin xyz="0 0 0" rpy="0 0 0"/>
        </xacro:inertial_cylinder>
    </link>
     <gazebo reference="left_wheel">
            <material>Gazebo/Black</material>
    </gazebo>
    <joint name="right_wheel_joint" type="continuous">
        <parent link="base_link"/>
        <child link="right_wheel"/> 
        <origin xyz="0.08 -0.087 0" rpy="${pi/2} 0 0"/>
        <axis xyz="0 0 -1"/>
    </joint>
    <link name="right_wheel">
        <visual>
            <geometry>
                <cylinder radius="0.035" length="0.017"/>
            </geometry>
            <material name="black"/>
        </visual>
        <collision>
            <geometry>
                <cylinder radius="0.035" length="0.017"/>
            </geometry>
        </collision>
        <xacro:inertial_cylinder mass="0.1" length="0.017" radius="0.035">
            <origin xyz="0 0 0" rpy="0 0 0"/>
        </xacro:inertial_cylinder>
    </link>
     <gazebo reference="right_wheel">
            <material>Gazebo/Black</material>
    </gazebo>
    <joint name="left_wheel_joint_b" type="continuous">
        <parent link="base_link"/>
        <child link="left_wheel_b"/> 
        <origin xyz="-0.06 0.087 0" rpy="-${pi/2} 0 0"/>
        <axis xyz="0 0 1"/>
    </joint>
    <link name="left_wheel_b">
        <visual>
            <geometry>
                <cylinder radius="0.035" length="0.017"/>
            </geometry>
            <material name="black"/>
        </visual>
        <collision>
            <geometry>
                <cylinder radius="0.035" length="0.017"/>
            </geometry>
        </collision>
        <xacro:inertial_cylinder mass="0.1" length="0.017" radius="0.035">
            <origin xyz="0 0 0" rpy="0 0 0"/>
        </xacro:inertial_cylinder>
    </link>
     <gazebo reference="left_wheel_b">
            <material>Gazebo/Black</material>
    </gazebo>
    <joint name="right_wheel_joint_b" type="continuous">
        <parent link="base_link"/>
        <child link="right_wheel_b"/> 
        <origin xyz="-0.06 -0.087 0" rpy="${pi/2} 0 0"/>
        <axis xyz="0 0 -1"/>
    </joint>
    <link name="right_wheel_b">
        <visual>
            <geometry>
                <cylinder radius="0.035" length="0.017"/>
            </geometry>
            <material name="black"/>
        </visual>
        <collision>
            <geometry>
                <cylinder radius="0.035" length="0.017"/>
            </geometry>
        </collision>
        <xacro:inertial_cylinder mass="0.1" length="0.017" radius="0.035">
            <origin xyz="0 0 0" rpy="0 0 0"/>
        </xacro:inertial_cylinder>
    </link>
     <gazebo reference="right_wheel_b">
            <material>Gazebo/Black</material>
    </gazebo>
    <!-- <joint name="caster_wheel_joint" type="fixed">
        <parent link="chassis"/>
        <child link="caster_wheel"/>
        <origin xyz="0.14 0 0"/>
    </joint> -->
    <!-- <link name="caster_wheel">
        <visual>
            <geometry>
                <sphere radius="0.035"/>
            </geometry>
            <material name="black"/>
        </visual>
        <collision>
            <geometry>
                <sphere radius="0.035"/>
            </geometry>
            <material name="black"/>
        </collision>
        <xacro:inertial_sphere mass="0.1" radius="0.035">
            <origin xyz="0 0 0" rpy="0 0 0"/>
        </xacro:inertial_sphere>
    </link>
    <gazebo reference="caster_wheel">
            <material>Gazebo/Silver</material>
            <mu1 value="0.001"/>
            <mu2 value="0.001"/>
    </gazebo> -->
</robot>